 from app import app
  File "/app/app.py", line 36, in <module>
    db.init_app(app)
  File "/opt/venv/lib/python3.11/site-packages/flask_sqlalchemy/extension.py", line 355, in init_app
    raise RuntimeError(
RuntimeError: Either 'SQLALCHEMY_DATABASE_URI' or 'SQLALCHEMY_BINDS' must be set.
[2024-12-27 14:31:54 +0000] [9] [INFO] Worker exiting (pid: 9)
[2024-12-27 14:31:54 +0000] [1] [ERROR] Worker (pid:9) exited with code 3
[2024-12-27 14:31:54 +0000] [1] [ERROR] Shutting down: Master
[2024-12-27 14:31:54 +0000] [1] [ERROR] Reason: Worker failed to boot.
[2024-12-27 14:31:56 +0000] [1] [INFO] Starting gunicorn 23.0.0
[2024-12-27 14:31:56 +0000] [1] [INFO] Listening at: http://0.0.0.0:8000 (1)
[2024-12-27 14:31:56 +0000] [1] [INFO] Using worker: sync
[2024-12-27 14:31:56 +0000] [9] [INFO] Booting worker with pid: 9
[2024-12-27 14:31:56 +0000] [9] [ERROR] Exception in worker process
Traceback (most recent call last):
  File "/opt/venv/lib/python3.11/site-packages/gunicorn/arbiter.py", line 608, in spawn_worker
    worker.init_process()
  File "/opt/venv/lib/python3.11/site-packages/gunicorn/workers/base.py", line 135, in init_process
    self.load_wsgi()
  File "/opt/venv/lib/python3.11/site-packages/gunicorn/workers/base.py", line 147, in load_wsgi
    self.wsgi = self.app.wsgi()
                ^^^^^^^^^^^^^^^
  File "/opt/venv/lib/python3.11/site-packages/gunicorn/app/base.py", line 66, in wsgi
    self.callable = self.load()
                    ^^^^^^^^^^^
  File "/opt/venv/lib/python3.11/site-packages/gunicorn/app/wsgiapp.py", line 57, in load
    return self.load_wsgiapp()
           ^^^^^^^^^^^^^^^^^^^
  File "/opt/venv/lib/python3.11/site-packages/gunicorn/app/wsgiapp.py", line 47, in load_wsgiapp
    return util.import_app(self.app_uri)
           ^^^^^^^^^^^^^^^^^^^^^^^^^^^^^
  File "/opt/venv/lib/python3.11/site-packages/gunicorn/util.py", line 370, in import_app
    mod = importlib.import_module(module)
          ^^^^^^^^^^^^^^^^^^^^^^^^^^^^^^^
  File "/root/.nix-profile/lib/python3.11/importlib/__init__.py", line 126, in import_module
    return _bootstrap._gcd_import(name[level:], package, level)
           ^^^^^^^^^^^^^^^^^^^^^^^^^^^^^^^^^^^^^^^^^^^^^^^^^^^^
  File "<frozen importlib._bootstrap>", line 1204, in _gcd_import
  File "<frozen importlib._bootstrap>", line 1176, in _find_and_load
  File "<frozen importlib._bootstrap>", line 1147, in _find_and_load_unlocked
  File "<frozen importlib._bootstrap>", line 690, in _load_unlocked
  File "<frozen importlib._bootstrap_external>", line 940, in exec_module
  File "<frozen importlib._bootstrap>", line 241, in _call_with_frames_removed
  File "/app/main.py", line 4, in <module>
    from app import app
  File "/app/app.py", line 36, in <module>
    db.init_app(app)
  File "/opt/venv/lib/python3.11/site-packages/flask_sqlalchemy/extension.py", line 355, in init_app
    raise RuntimeError(
RuntimeError: Either 'SQLALCHEMY_DATABASE_URI' or 'SQLALCHEMY_BINDS' must be set.
[2024-12-27 14:31:56 +0000] [9] [INFO] Worker exiting (pid: 9)
[2024-12-27 14:31:56 +0000] [1] [ERROR] Worker (pid:9) exited with code 3
[2024-12-27 14:31:56 +0000] [1] [ERROR] Shutting down: Master
[2024-12-27 14:31:56 +0000] [1] [ERROR] Reason: Worker failed to boot.
[2024-12-27 14:31:58 +0000] [1] [INFO] Starting gunicorn 23.0.0
[2024-12-27 14:31:58 +0000] [1] [INFO] Listening at: http://0.0.0.0:8000 (1)
[2024-12-27 14:31:58 +0000] [1] [INFO] Using worker: sync
[2024-12-27 14:31:58 +0000] [9] [INFO] Booting worker with pid: 9
[2024-12-27 14:31:59 +0000] [9] [ERROR] Exception in worker process
Traceback (most recent call last):
  File "/opt/venv/lib/python3.11/site-packages/gunicorn/arbiter.py", line 608, in spawn_worker
    worker.init_process()
  File "/opt/venv/lib/python3.11/site-packages/gunicorn/workers/base.py", line 135, in init_process
    self.load_wsgi()
  File "/opt/venv/lib/python3.11/site-packages/gunicorn/workers/base.py", line 147, in load_wsgi
    self.wsgi = self.app.wsgi()
                ^^^^^^^^^^^^^^^
  File "/opt/venv/lib/python3.11/site-packages/gunicorn/app/base.py", line 66, in wsgi
    self.callable = self.load()
                    ^^^^^^^^^^^
  File "/opt/venv/lib/python3.11/site-packages/gunicorn/app/wsgiapp.py", line 57, in load
    return self.load_wsgiapp()
           ^^^^^^^^^^^^^^^^^^^
  File "/opt/venv/lib/python3.11/site-packages/gunicorn/app/wsgiapp.py", line 47, in load_wsgiapp
    return util.import_app(self.app_uri)
           ^^^^^^^^^^^^^^^^^^^^^^^^^^^^^
  File "/opt/venv/lib/python3.11/site-packages/gunicorn/util.py", line 370, in import_app
    mod = importlib.import_module(module)
          ^^^^^^^^^^^^^^^^^^^^^^^^^^^^^^^
  File "/root/.nix-profile/lib/python3.11/importlib/__init__.py", line 126, in import_module
    return _bootstrap._gcd_import(name[level:], package, level)
           ^^^^^^^^^^^^^^^^^^^^^^^^^^^^^^^^^^^^^^^^^^^^^^^^^^^^
  File "<frozen importlib._bootstrap>", line 1204, in _gcd_import
  File "<frozen importlib._bootstrap>", line 1176, in _find_and_load
  File "<frozen importlib._bootstrap>", line 1147, in _find_and_load_unlocked
  File "<frozen importlib._bootstrap>", line 690, in _load_unlocked
  File "<frozen importlib._bootstrap_external>", line 940, in exec_module
  File "<frozen importlib._bootstrap>", line 241, in _call_with_frames_removed
  File "/app/main.py", line 4, in <module>
    from app import app
  File "/app/app.py", line 36, in <module>
    db.init_app(app)
  File "/opt/venv/lib/python3.11/site-packages/flask_sqlalchemy/extension.py", line 355, in init_app
    raise RuntimeError(
RuntimeError: Either 'SQLALCHEMY_DATABASE_URI' or 'SQLALCHEMY_BINDS' must be set.
[2024-12-27 14:31:59 +0000] [9] [INFO] Worker exiting (pid: 9)
[2024-12-27 14:31:59 +0000] [1] [ERROR] Worker (pid:9) exited with code 3
[2024-12-27 14:31:59 +0000] [1] [ERROR] Shutting down: Master
[2024-12-27 14:31:59 +0000] [1] [ERROR] Reason: Worker failed to boot.